Workbook

Sheet Instrucciones
A1: Evaluación a ciegas con la rúbrica de 5 criterios — Evaluador 1
A2: Tesis: LLM como asistentes de programación PLC en la academia (UTP). 600 respuestas de código de 25 tareas (generación y conversión), cada una con un código que no revela el modelo ni la estrategia.
A4: Qué hay que hacer
A5: 1. Trabaja una tarea completa antes de pasar a la siguiente. Abre respuestas/Respuestas_<tarea>.html (enunciado, protocolo de prueba y respuestas por código) y la hoja de la misma tarea en este libro.
A6: 2. Rellena ÚNICAMENTE las celdas amarillas con 0, 1, 2 o 3 según la hoja Rúbrica. Las celdas azules vienen de CODESYS o se calculan solas.
A7: 3. Justifica cada puntuación en una línea, en la columna de justificación correspondiente. Sin justificación, la puntuación no es auditable.
A8: 4. La fila gris EJEMPLO solo muestra el formato. No se analiza.
A9: 5. Puedes repartir el trabajo en varias sesiones. La tabla de avance de abajo indica qué falta. Guarda con el mismo nombre.
A11: Reglas de decisión (fijadas antes de evaluar; no se cambian durante la evaluación)
A12: Si la respuesta NO compila: Cumplimiento IEC = 0 y Corrección funcional = 0. Ya están precargadas. Los otros tres criterios se evalúan igual, leyendo el código.
A13: Si la respuesta pasa TODOS los pasos del harness: Corrección funcional = 3. Ya está precargada.
A14: Si compila pero falla pasos del harness: Corrección funcional es 0, 1 o 2 según la rúbrica. El HTML indica qué pasos fallaron y el protocolo de prueba dice qué comprueba cada paso.
... A23: Avance
A24: Tarea | B24: Respuestas | C24: Completas | D24: Pendientes
A25: B1 | B25: 24 | C25: =COUNTIF(B1!N6:N29,"Completa") -> 0 | D25: =B25-C25 -> 24
A26: B2 | B26: 24 | C26: =COUNTIF(B2!N6:N29,"Completa") -> 0 | D26: =B26-C26 -> 24
A27: B3 | B27: 24 | C27: =COUNTIF(B3!N6:N29,"Completa") -> 0 | D27: =B27-C27 -> 24
A28: B4 | B28: 24 | C28: =COUNTIF(B4!N6:N29,"Completa") -> 0 | D28: =B28-C28 -> 24
A29: B5 | B29: 24 | C29: =COUNTIF(B5!N6:N29,"Completa") -> 0 | D29: =B29-C29 -> 24
A30: B6 | B30: 24 | C30: =COUNTIF(B6!N6:N29,"Completa") -> 0 | D30: =B30-C30 -> 24
A31: B7 | B31: 24 | C31: =COUNTIF(B7!N6:N29,"Completa") -> 0 | D31: =B31-C31 -> 24
A32: B8 | B32: 24 | C32: =COUNTIF(B8!N6:N29,"Completa") -> 0 | D32: =B32-C32 -> 24
A33: I1 | B33: 24 | C33: =COUNTIF(I1!N6:N29,"Completa") -> 0 | D33: =B33-C33 -> 24
A34: I2 | B34: 24 | C34: =COUNTIF(I2!N6:N29,"Completa") -> 0 | D34: =B34-C34 -> 24
A35: I3 | B35: 24 | C35: =COUNTIF(I3!N6:N29,"Completa") -> 0 | D35: =B35-C35 -> 24
A36: I4 | B36: 24 | C36: =COUNTIF(I4!N6:N29,"Completa") -> 0 | D36: =B36-C36 -> 24
A37: I5 | B37: 24 | C37: =COUNTIF(I5!N6:N29,"Completa") -> 0 | D37: =B37-C37 -> 24
A38: I6 | B38: 24 | C38: =COUNTIF(I6!N6:N29,"Completa") -> 0 | D38: =B38-C38 -> 24
A39: I7 | B39: 24 | C39: =COUNTIF(I7!N6:N29,"Completa") -> 0 | D39: =B39-C39 -> 24
A40: I8 | B40: 24 | C40: =COUNTIF(I8!N6:N29,"Completa") -> 0 | D40: =B40-C40 -> 24
A41: A1 | B41: 24 | C41: =COUNTIF(A1!N6:N29,"Completa") -> 0 | D41: =B41-C41 -> 24
A42: A2 | B42: 24 | C42: =COUNTIF(A2!N6:N29,"Completa") -> 0 | D42: =B42-C42 -> 24
A43: A3 | B43: 24 | C43: =COUNTIF(A3!N6:N29,"Completa") -> 0 | D43: =B43-C43 -> 24
A44: A4 | B44: 24 | C44: =COUNTIF(A4!N6:N29,"Completa") -> 0 | D44: =B44-C44 -> 24
A45: A5 | B45: 24 | C45: =COUNTIF(A5!N6:N29,"Completa") -> 0 | D45: =B45-C45 -> 24
A46: A6 | B46: 24 | C46: =COUNTIF(A6!N6:N29,"Completa") -> 0 | D46: =B46-C46 -> 24
A47: C3 | B47: 24 | C47: =COUNTIF(C3!N6:N29,"Completa") -> 0 | D47: =B47-C47 -> 24
A48: C7 | B48: 24 | C48: =COUNTIF(C7!N6:N29,"Completa") -> 0 | D48: =B48-C48 -> 24
A49: C8 | B49: 24 | C49: =COUNTIF(C8!N6:N29,"Completa") -> 0 | D49: =B49-C49 -> 24
A50: Total | B50: =SUM(B25:B49) -> 600 | C50: =SUM(C25:C49) -> 0 | D50: =SUM(D25:D49) -> 600
...

Sheet Rúbrica
A1: Rúbrica de evaluación — 5 criterios × 4 niveles
A2: Fuente: Banco_de_Pruebas_v0.xlsx, hoja Rúbrica (2.5), sin cambios de redacción. Insuficiente = 0, Básico = 1, Competente = 2, Excelente = 3.
A4: Criterio | B4: Insuficiente (0) | C4: Básico (1) | D4: Competente (2) | E4: Excelente (3) | F4: Fuente del criterio
A5: Corrección funcional | B5: No implementa la lógica pedida o falla en el caso nominal. | C5: Funciona en el caso nominal pero falla en casos límite evidentes (flancos, reset, E-stop). | D5: Correcto en el caso nominal y en la mayoría de los casos límite; fallas menores sin riesgo. | E5: Correcto en todos los casos probados, incluidos límites y secuencias de fallo. | F5: IEC 61508 / simulación CODESYS
A6: Cumplimiento IEC 61131-3 | B6: No compila; sintaxis o declaraciones inválidas. | C6: Compila solo tras correcciones menores, o usa extensiones fuera del estándar. | D6: Compila sin cambios; declaraciones y tipos correctos. | E6: Compila sin cambios y usa construcciones idiomáticas del estándar (POU adecuado, tipos TIME correctos, FB estándar bien instanciados). | F6: IEC 61131-3 / compilador CODESYS
A7: Coherencia lógica | B7: Condiciones contradictorias, variables sin inicializar con efecto, o estados muertos que impiden operar. | C7: Lógica mayormente coherente con redundancias o condiciones muertas sin efecto grave. | D7: Sin contradicciones; inicialización correcta; transiciones completas. | E7: Además, robusta: interlocks completos, sin estados inalcanzables, comportamiento seguro ante entradas simultáneas. | F7: Análisis técnico + simulación
A8: Claridad estructural | B8: Sin estructura reconocible; nombres crípticos; sin comentarios. | C8: Estructura básica pero nombres pobres o comentarios ausentes/incorrectos. | D8: Nombres descriptivos, secciones ordenadas, comentarios útiles. | E8: Además, modularización adecuada (FB reutilizable, separación lógica/E/S) y comentarios que explican el porqué. | F8: Clean Code (Martin)
A9: Mantenibilidad | B9: Valores mágicos por doquier; imposible modificar sin reescribir. | C9: Modificable con esfuerzo; constantes parcialmente parametrizadas. | D9: Parámetros como variables/constantes declaradas; cambios localizados. | E9: Además, diseño extensible (parámetros de entrada del FB, sin duplicación de lógica). | F9: ISO/IEC 25010

Sheet B1
A1: B1 — Arranque/paro de motor con enclavamiento (Basico)
A2: Lee cada respuesta por su código en respuestas/Respuestas_B1.html. Rellena solo las celdas amarillas. Las azules vienen de CODESYS o se calculan solas. La fila EJEMPLO no se analiza.
A4: Código | B4: Resultado en CODESYS (automático) | C4: Corrección funcional (0–3) | D4: Cumplimiento IEC (0–3) | E4: Coherencia lógica (0–3) | F4: Claridad estructural (0–3) | G4: Mantenibilidad (0–3) | H4: Total (0–15) | I4: Justificación: corrección funcional / IEC | J4: Justificación: coherencia | K4: Justificación: claridad | L4: Justificación: mantenibilidad | M4: Observaciones | N4: Estado
A5: EJEMPLO | B5: Compila. Falla 2 de 7 pasos del harness (pasos 3,5; numerados desde 0). | C5: 1 | D5: 2 | E5: 2 | F5: 2 | G5: 1 | H5: =IF(COUNT(C5:G5)=5,SUM(C5:G5),"") -> 8 | I5: Arranca y para, pero rearranca solo tras la emergencia. | J5: Sin contradicciones; transiciones completas. | K5: Nombres claros, comentarios útiles. | L5: El tiempo está escrito como literal en dos sitios. | N5: =IF(COUNT(C5:G5)=5,"Completa","Falta") -> Completa
A6: B1-3577 | B6: Compila. Pasa los 7 pasos del harness. | C6: 3 | H6: =IF(COUNT(C6:G6)=5,SUM(C6:G6),"") | N6: =IF(COUNT(C6:G6)=5,"Completa","Falta") -> Falta
A7: B1-8070 | B7: No compila (12 errores). | C7: 0 | D7: 0 | H7: =IF(COUNT(C7:G7)=5,SUM(C7:G7),"") | N7: =IF(COUNT(C7:G7)=5,"Completa","Falta") -> Falta
A8: B1-4667 | B8: Compila. Pasa los 7 pasos del harness. | C8: 3 | H8: =IF(COUNT(C8:G8)=5,SUM(C8:G8),"") | N8: =IF(COUNT(C8:G8)=5,"Completa","Falta") -> Falta
A9: B1-3153 | B9: Compila. Falla 1 de 7 pasos del harness (pasos 6; numerados desde 0). | H9: =IF(COUNT(C9:G9)=5,SUM(C9:G9),"") | N9: =IF(COUNT(C9:G9)=5,"Completa","Falta") -> Falta
A10: B1-3916 | B10: Compila. Pasa los 7 pasos del harness. | C10: 3 | H10: =IF(COUNT(C10:G10)=5,SUM(C10:G10),"") | N10: =IF(COUNT(C10:G10)=5,"Completa","Falta") -> Falta
A11: B1-4316 | B11: Compila. Pasa los 7 pasos del harness. | C11: 3 | H11: =IF(COUNT(C11:G11)=5,SUM(C11:G11),"") | N11: =IF(COUNT(C11:G11)=5,"Completa","Falta") -> Falta
A12: B1-7103 | B12: Compila. Falla 1 de 7 pasos del harness (pasos 6; numerados desde 0). | H12: =IF(COUNT(C12:G12)=5,SUM(C12:G12),"") | N12: =IF(COUNT(C12:G12)=5,"Completa","Falta") -> Falta
A13: B1-3006 | B13: Compila. Pasa los 7 pasos del harness. | C13: 3 | H13: =IF(COUNT(C13:G13)=5,SUM(C13:G13),"") | N13: =IF(COUNT(C13:G13)=5,"Completa","Falta") -> Falta
A14: B1-7637 | B14: Compila. Pasa los 7 pasos del harness. | C14: 3 | H14: =IF(COUNT(C14:G14)=5,SUM(C14:G14),"") | N14: =IF(COUNT(C14:G14)=5,"Completa","Falta") -> Falta
A15: B1-3504 | B15: Compila. Pasa los 7 pasos del harness. | C15: 3 | H15: =IF(COUNT(C15:G15)=5,SUM(C15:G15),"") | N15: =IF(COUNT(C15:G15)=5,"Completa","Falta") -> Falta
A16: B1-1729 | B16: Compila. Pasa los 7 pasos del harness. | C16: 3 | H16: =IF(COUNT(C16:G16)=5,SUM(C16:G16),"") | N16: =IF(COUNT(C16:G16)=5,"Completa","Falta") -> Falta
A17: B1-8468 | B17: Compila. Pasa los 7 pasos del harness. | C17: 3 | H17: =IF(COUNT(C17:G17)=5,SUM(C17:G17),"") | N17: =IF(COUNT(C17:G17)=5,"Completa","Falta") -> Falta
A18: B1-2708 | B18: Compila. Falla 1 de 7 pasos del harness (pasos 6; numerados desde 0). | H18: =IF(COUNT(C18:G18)=5,SUM(C18:G18),"") | N18: =IF(COUNT(C18:G18)=5,"Completa","Falta") -> Falta
A19: B1-7716 | B19: Compila. Pasa los 7 pasos del harness. | C19: 3 | H19: =IF(COUNT(C19:G19)=5,SUM(C19:G19),"") | N19: =IF(COUNT(C19:G19)=5,"Completa","Falta") -> Falta
A20: B1-4160 | B20: No compila (12 errores). | C20: 0 | D20: 0 | H20: =IF(COUNT(C20:G20)=5,SUM(C20:G20),"") | N20: =IF(COUNT(C20:G20)=5,"Completa","Falta") -> Falta
A21: B1-3776 | B21: Compila. Pasa los 7 pasos del harness. | C21: 3 | H21: =IF(COUNT(C21:G21)=5,SUM(C21:G21),"") | N21: =IF(COUNT(C21:G21)=5,"Completa","Falta") -> Falta
A22: B1-1689 | B22: Compila. Falla 1 de 7 pasos del harness (pasos 6; numerados desde 0). | H22: =IF(COUNT(C22:G22)=5,SUM(C22:G22),"") | N22: =IF(COUNT(C22:G22)=5,"Completa","Falta") -> Falta
A23: B1-7970 | B23: Compila. Falla 1 de 7 pasos del harness (pasos 6; numerados desde 0). | H23: =IF(COUNT(C23:G23)=5,SUM(C23:G23),"") | N23: =IF(COUNT(C23:G23)=5,"Completa","Falta") -> Falta
A24: B1-2577 | B24: Compila. Pasa los 7 pasos del harness. | C24: 3 | H24: =IF(COUNT(C24:G24)=5,SUM(C24:G24),"") | N24: =IF(COUNT(C24:G24)=5,"Completa","Falta") -> Falta
A25: B1-2078 | B25: Compila. Pasa los 7 pasos del harness. | C25: 3 | H25: =IF(COUNT(C25:G25)=5,SUM(C25:G25),"") | N25: =IF(COUNT(C25:G25)=5,"Completa","Falta") -> Falta
A26: B1-2077 | B26: Compila. Pasa los 7 pasos del harness. | C26: 3 | H26: =IF(COUNT(C26:G26)=5,SUM(C26:G26),"") | N26: =IF(COUNT(C26:G26)=5,"Completa","Falta") -> Falta
A27: B1-6475 | B27: Compila. Pasa los 7 pasos del harness. | C27: 3 | H27: =IF(COUNT(C27:G27)=5,SUM(C27:G27),"") | N27: =IF(COUNT(C27:G27)=5,"Completa","Falta") -> Falta
A28: B1-9711 | B28: Compila. Pasa los 7 pasos del harness. | C28: 3 | H28: =IF(COUNT(C28:G28)=5,SUM(C28:G28),"") | N28: =IF(COUNT(C28:G28)=5,"Completa","Falta") -> Falta
A29: B1-4469 | B29: Compila. Falla 1 de 7 pasos del harness (pasos 6; numerados desde 0). | H29: =IF(COUNT(C29:G29)=5,SUM(C29:G29),"") | N29: =IF(COUNT(C29:G29)=5,"Completa","Falta") -> Falta

Sheet B2
A1: B2 — Válvula con retardo TON (Basico)
A2: Lee cada respuesta por su código en respuestas/Respuestas_B2.html. Rellena solo las celdas amarillas. Las azules vienen de CODESYS o se calculan solas. La fila EJEMPLO no se analiza.
A4: Código | B4: Resultado en CODESYS (automático) | C4: Corrección funcional (0–3) | D4: Cumplimiento IEC (0–3) | E4: Coherencia lógica (0–3) | F4: Claridad estructural (0–3) | G4: Mantenibilidad (0–3) | H4: Total (0–15) | I4: Justificación: corrección funcional / IEC | J4: Justificación: coherencia | K4: Justificación: claridad | L4: Justificación: mantenibilidad | M4: Observaciones | N4: Estado
A5: EJEMPLO | B5: Compila. Falla 2 de 7 pasos del harness (pasos 3,5; numerados desde 0). | C5: 1 | D5: 2 | E5: 2 | F5: 2 | G5: 1 | H5: =IF(COUNT(C5:G5)=5,SUM(C5:G5),"") -> 8 | I5: Arranca y para, pero rearranca solo tras la emergencia. | J5: Sin contradicciones; transiciones completas. | K5: Nombres claros, comentarios útiles. | L5: El tiempo está escrito como literal en dos sitios. | N5: =IF(COUNT(C5:G5)=5,"Completa","Falta") -> Completa
A6: B2-9847 | B6: Compila. Pasa los 6 pasos del harness. | C6: 3 | H6: =IF(COUNT(C6:G6)=5,SUM(C6:G6),"") | N6: =IF(COUNT(C6:G6)=5,"Completa","Falta") -> Falta
A7: B2-6674 | B7: Compila. Pasa los 6 pasos del harness. | C7: 3 | H7: =IF(COUNT(C7:G7)=5,SUM(C7:G7),"") | N7: =IF(COUNT(C7:G7)=5,"Completa","Falta") -> Falta
A8: B2-1651 | B8: Compila. Pasa los 6 pasos del harness. | C8: 3 | H8: =IF(COUNT(C8:G8)=5,SUM(C8:G8),"") | N8: =IF(COUNT(C8:G8)=5,"Completa","Falta") -> Falta
A9: B2-3609 | B9: Compila. Pasa los 6 pasos del harness. | C9: 3 | H9: =IF(COUNT(C9:G9)=5,SUM(C9:G9),"") | N9: =IF(COUNT(C9:G9)=5,"Completa","Falta") -> Falta
A10: B2-5560 | B10: Compila. Pasa los 6 pasos del harness. | C10: 3 | H10: =IF(COUNT(C10:G10)=5,SUM(C10:G10),"") | N10: =IF(COUNT(C10:G10)=5,"Completa","Falta") -> Falta
A11: B2-5675 | B11: Compila. Pasa los 6 pasos del harness. | C11: 3 | H11: =IF(COUNT(C11:G11)=5,SUM(C11:G11),"") | N11: =IF(COUNT(C11:G11)=5,"Completa","Falta") -> Falta
A12: B2-7015 | B12: Compila. Pasa los 6 pasos del harness. | C12: 3 | H12: =IF(COUNT(C12:G12)=5,SUM(C12:G12),"") | N12: =IF(COUNT(C12:G12)=5,"Completa","Falta") -> Falta
A13: B2-6278 | B13: Compila. Pasa los 6 pasos del harness. | C13: 3 | H13: =IF(COUNT(C13:G13)=5,SUM(C13:G13),"") | N13: =IF(COUNT(C13:G13)=5,"Completa","Falta") -> Falta
A14: B2-3727 | B14: Compila. Falla 3 de 6 pasos del harness (pasos 1,2,4; numerados desde 0). | H14: =IF(COUNT(C14:G14)=5,SUM(C14:G14),"") | N14: =IF(COUNT(C14:G14)=5,"Completa","Falta") -> Falta
A15: B2-6755 | B15: Compila. Pasa los 6 pasos del harness. | C15: 3 | H15: =IF(COUNT(C15:G15)=5,SUM(C15:G15),"") | N15: =IF(COUNT(C15:G15)=5,"Completa","Falta") -> Falta
A16: B2-7829 | B16: Compila. Falla 3 de 6 pasos del harness (pasos 1,2,4; numerados desde 0). | H16: =IF(COUNT(C16:G16)=5,SUM(C16:G16),"") | N16: =IF(COUNT(C16:G16)=5,"Completa","Falta") -> Falta
A17: B2-7426 | B17: Compila. Pasa los 6 pasos del harness. | C17: 3 | H17: =IF(COUNT(C17:G17)=5,SUM(C17:G17),"") | N17: =IF(COUNT(C17:G17)=5,"Completa","Falta") -> Falta
A18: B2-8183 | B18: Compila. Pasa los 6 pasos del harness. | C18: 3 | H18: =IF(COUNT(C18:G18)=5,SUM(C18:G18),"") | N18: =IF(COUNT(C18:G18)=5,"Completa","Falta") -> Falta
A19: B2-4395 | B19: Compila. Pasa los 6 pasos del harness. | C19: 3 | H19: =IF(COUNT(C19:G19)=5,SUM(C19:G19),"") | N19: =IF(COUNT(C19:G19)=5,"Completa","Falta") -> Falta
A20: B2-4528 | B20: Compila. Pasa los 6 pasos del harness. | C20: 3 | H20: =IF(COUNT(C20:G20)=5,SUM(C20:G20),"") | N20: =IF(COUNT(C20:G20)=5,"Completa","Falta") -> Falta
A21: B2-8816 | B21: Compila. Pasa los 6 pasos del harness. | C21: 3 | H21: =IF(COUNT(C21:G21)=5,SUM(C21:G21),"") | N21: =IF(COUNT(C21:G21)=5,"Completa","Falta") -> Falta
A22: B2-9944 | B22: Compila. Pasa los 6 pasos del harness. | C22: 3 | H22: =IF(COUNT(C22:G22)=5,SUM(C22:G22),"") | N22: =IF(COUNT(C22:G22)=5,"Completa","Falta") -> Falta
A23: B2-6018 | B23: Compila. Pasa los 6 pasos del harness. | C23: 3 | H23: =IF(COUNT(C23:G23)=5,SUM(C23:G23),"") | N23: =IF(COUNT(C23:G23)=5,"Completa","Falta") -> Falta
A24: B2-4891 | B24: Compila sola, pero no se pudo simular: declara las entradas donde el harness no puede escribirlas ('nivelAlto' no es ninguna entrada de 'FB_VALVULA'). | H24: =IF(COUNT(C24:G24)=5,SUM(C24:G24),"") | N24: =IF(COUNT(C24:G24)=5,"Completa","Falta") -> Falta
A25: B2-3672 | B25: Compila. Pasa los 6 pasos del harness. | C25: 3 | H25: =IF(COUNT(C25:G25)=5,SUM(C25:G25),"") | N25: =IF(COUNT(C25:G25)=5,"Completa","Falta") -> Falta
A26: B2-5243 | B26: Compila. Falla 1 de 6 pasos del harness (pasos 1; numerados desde 0). | H26: =IF(COUNT(C26:G26)=5,SUM(C26:G26),"") | N26: =IF(COUNT(C26:G26)=5,"Completa","Falta") -> Falta
A27: B2-6383 | B27: Compila. Pasa los 6 pasos del harness. | C27: 3 | H27: =IF(COUNT(C27:G27)=5,SUM(C27:G27),"") | N27: =IF(COUNT(C27:G27)=5,"Completa","Falta") -> Falta
A28: B2-2583 | B28: Compila. Falla 3 de 6 pasos del harness (pasos 1,2,4; numerados desde 0). | H28: =IF(COUNT(C28:G28)=5,SUM(C28:G28),"") | N28: =IF(COUNT(C28:G28)=5,"Completa","Falta") -> Falta
A29: B2-2211 | B29: Compila. Pasa los 6 pasos del harness. | C29: 3 | H29: =IF(COUNT(C29:G29)=5,SUM(C29:G29),"") | N29: =IF(COUNT(C29:G29)=5,"Completa","Falta") -> Falta

Sheet B3
A1: B3 — Contador de piezas con preset (Basico)
A2: Lee cada respuesta por su código en respuestas/Respuestas_B3.html. Rellena solo las celdas amarillas. Las azules vienen de CODESYS o se calculan solas. La fila EJEMPLO no se analiza.
A4: Código | B4: Resultado en CODESYS (automático) | C4: Corrección funcional (0–3) | D4: Cumplimiento IEC (0–3) | E4: Coherencia lógica (0–3) | F4: Claridad estructural (0–3) | G4: Mantenibilidad (0–3) | H4: Total (0–15) | I4: Justificación: corrección funcional / IEC | J4: Justificación: coherencia | K4: Justificación: claridad | L4: Justificación: mantenibilidad | M4: Observaciones | N4: Estado
A5: EJEMPLO | B5: Compila. Falla 2 de 7 pasos del harness (pasos 3,5; numerados desde 0). | C5: 1 | D5: 2 | E5: 2 | F5: 2 | G5: 1 | H5: =IF(COUNT(C5:G5)=5,SUM(C5:G5),"") -> 8 | I5: Arranca y para, pero rearranca solo tras la emergencia. | J5: Sin contradicciones; transiciones completas. | K5: Nombres claros, comentarios útiles. | L5: El tiempo está escrito como literal en dos sitios. | N5: =IF(COUNT(C5:G5)=5,"Completa","Falta") -> Completa
A6: B3-6721 | B6: Compila. Pasa los 7 pasos del harness. | C6: 3 | H6: =IF(COUNT(C6:G6)=5,SUM(C6:G6),"") | N6: =IF(COUNT(C6:G6)=5,"Completa","Falta") -> Falta
A7: B3-4690 | B7: Compila. Falla 5 de 7 pasos del harness (pasos 1,2,3,4,5; numerados desde 0). | H7: =IF(COUNT(C7:G7)=5,SUM(C7:G7),"") | N7: =IF(COUNT(C7:G7)=5,"Completa","Falta") -> Falta
A8: B3-5495 | B8: Compila. Pasa los 7 pasos del harness. | C8: 3 | H8: =IF(COUNT(C8:G8)=5,SUM(C8:G8),"") | N8: =IF(COUNT(C8:G8)=5,"Completa","Falta") -> Falta
A9: B3-6597 | B9: Compila. Pasa los 7 pasos del harness. | C9: 3 | H9: =IF(COUNT(C9:G9)=5,SUM(C9:G9),"") | N9: =IF(COUNT(C9:G9)=5,"Completa","Falta") -> Falta
A10: B3-8516 | B10: Compila. Pasa los 7 pasos del harness. | C10: 3 | H10: =IF(COUNT(C10:G10)=5,SUM(C10:G10),"") | N10: =IF(COUNT(C10:G10)=5,"Completa","Falta") -> Falta
A11: B3-4736 | B11: Compila. Falla 5 de 7 pasos del harness (pasos 1,2,3,4,5; numerados desde 0). | H11: =IF(COUNT(C11:G11)=5,SUM(C11:G11),"") | N11: =IF(COUNT(C11:G11)=5,"Completa","Falta") -> Falta
A12: B3-6421 | B12: Compila. Pasa los 7 pasos del harness. | C12: 3 | H12: =IF(COUNT(C12:G12)=5,SUM(C12:G12),"") | N12: =IF(COUNT(C12:G12)=5,"Completa","Falta") -> Falta
A13: B3-8845 | B13: Compila. Pasa los 7 pasos del harness. | C13: 3 | H13: =IF(COUNT(C13:G13)=5,SUM(C13:G13),"") | N13: =IF(COUNT(C13:G13)=5,"Completa","Falta") -> Falta
A14: B3-9202 | B14: No compila (6 errores). | C14: 0 | D14: 0 | H14: =IF(COUNT(C14:G14)=5,SUM(C14:G14),"") | N14: =IF(COUNT(C14:G14)=5,"Completa","Falta") -> Falta
A15: B3-5228 | B15: Compila. Pasa los 7 pasos del harness. | C15: 3 | H15: =IF(COUNT(C15:G15)=5,SUM(C15:G15),"") | N15: =IF(COUNT(C15:G15)=5,"Completa","Falta") -> Falta
A16: B3-2786 | B16: Compila. Pasa los 7 pasos del harness. | C16: 3 | H16: =IF(COUNT(C16:G16)=5,SUM(C16:G16),"") | N16: =IF(COUNT(C16:G16)=5,"Completa","Falta") -> Falta
A17: B3-5689 | B17: Compila. Pasa los 7 pasos del harness. | C17: 3 | H17: =IF(COUNT(C17:G17)=5,SUM(C17:G17),"") | N17: =IF(COUNT(C17:G17)=5,"Completa","Falta") -> Falta
A18: B3-3133 | B18: Compila. Pasa los 7 pasos del harness. | C18: 3 | H18: =IF(COUNT(C18:G18)=5,SUM(C18:G18),"") | N18: =IF(COUNT(C18:G18)=5,"Completa","Falta") -> Falta
A19: B3-3078 | B19: Compila. Pasa los 7 pasos del harness. | C19: 3 | H19: =IF(COUNT(C19:G19)=5,SUM(C19:G19),"") | N19: =IF(COUNT(C19:G19)=5,"Completa","Falta") -> Falta
A20: B3-8293 | B20: Compila. Pasa los 7 pasos del harness. | C20: 3 | H20: =IF(COUNT(C20:G20)=5,SUM(C20:G20),"") | N20: =IF(COUNT(C20:G20)=5,"Completa","Falta") -> Falta
A21: B3-2446 | B21: Compila. Pasa los 7 pasos del harness. | C21: 3 | H21: =IF(COUNT(C21:G21)=5,SUM(C21:G21),"") | N21: =IF(COUNT(C21:G21)=5,"Completa","Falta") -> Falta
A22: B3-6547 | B22: Compila. Pasa los 7 pasos del harness. | C22: 3 | H22: =IF(COUNT(C22:G22)=5,SUM(C22:G22),"") | N22: =IF(COUNT(C22:G22)=5,"Completa","Falta") -> Falta
A23: B3-3429 | B23: Compila. Pasa los 7 pasos del harness. | C23: 3 | H23: =IF(COUNT(C23:G23)=5,SUM(C23:G23),"") | N23: =IF(COUNT(C23:G23)=5,"Completa","Falta") -> Falta
A24: B3-6741 | B24: Compila. Pasa los 7 pasos del harness. | C24: 3 | H24: =IF(COUNT(C24:G24)=5,SUM(C24:G24),"") | N24: =IF(COUNT(C24:G24)=5,"Completa","Falta") -> Falta
A25: B3-3465 | B25: Compila. Pasa los 7 pasos del harness. | C25: 3 | H25: =IF(COUNT(C25:G25)=5,SUM(C25:G25),"") | N25: =IF(COUNT(C25:G25)=5,"Completa","Falta") -> Falta
A26: B3-4741 | B26: Compila. Pasa los 7 pasos del harness. | C26: 3 | H26: =IF(COUNT(C26:G26)=5,SUM(C26:G26),"") | N26: =IF(COUNT(C26:G26)=5,"Completa","Falta") -> Falta
A27: B3-1730 | B27: Compila. Pasa los 7 pasos del harness. | C27: 3 | H27: =IF(COUNT(C27:G27)=5,SUM(C27:G27),"") | N27: =IF(COUNT(C27:G27)=5,"Completa","Falta") -> Falta
A28: B3-6937 | B28: Compila. Falla 3 de 7 pasos del harness (pasos 3,4,5; numerados desde 0). | H28: =IF(COUNT(C28:G28)=5,SUM(C28:G28),"") | N28: =IF(COUNT(C28:G28)=5,"Completa","Falta") -> Falta
A29: B3-2730 | B29: Compila. Pasa los 7 pasos del harness. | C29: 3 | H29: =IF(COUNT(C29:G29)=5,SUM(C29:G29),"") | N29: =IF(COUNT(C29:G29)=5,"Completa","Falta") -> Falta

Sheet B4
A1: B4 — Inversión de giro con enclavamiento cruzado (Basico)
A2: Lee cada respuesta por su código en respuestas/Respuestas_B4.html. Rellena solo las celdas amarillas. Las azules vienen de CODESYS o se calculan solas. La fila EJEMPLO no se analiza.
A4: Código | B4: Resultado en CODESYS (automático) | C4: Corrección funcional (0–3) | D4: Cumplimiento IEC (0–3) | E4: Coherencia lógica (0–3) | F4: Claridad estructural (0–3) | G4: Mantenibilidad (0–3) | H4: Total (0–15) | I4: Justificación: corrección funcional / IEC | J4: Justificación: coherencia | K4: Justificación: claridad | L4: Justificación: mantenibilidad | M4: Observaciones | N4: Estado
A5: EJEMPLO | B5: Compila. Falla 2 de 7 pasos del harness (pasos 3,5; numerados desde 0). | C5: 1 | D5: 2 | E5: 2 | F5: 2 | G5: 1 | H5: =IF(COUNT(C5:G5)=5,SUM(C5:G5),"") -> 8 | I5: Arranca y para, pero rearranca solo tras la emergencia. | J5: Sin contradicciones; transiciones completas. | K5: Nombres claros, comentarios útiles. | L5: El tiempo está escrito como literal en dos sitios. | N5: =IF(COUNT(C5:G5)=5,"Completa","Falta") -> Completa
A6: B4-8136 | B6: Compila. Falla 4 de 10 pasos del harness (pasos 3,4,7,9; numerados desde 0). | H6: =IF(COUNT(C6:G6)=5,SUM(C6:G6),"") | N6: =IF(COUNT(C6:G6)=5,"Completa","Falta") -> Falta
A7: B4-1620 | B7: Compila. Pasa los 10 pasos del harness. | C7: 3 | H7: =IF(COUNT(C7:G7)=5,SUM(C7:G7),"") | N7: =IF(COUNT(C7:G7)=5,"Completa","Falta") -> Falta
A8: B4-8880 | B8: Compila. Pasa los 10 pasos del harness. | C8: 3 | H8: =IF(COUNT(C8:G8)=5,SUM(C8:G8),"") | N8: =IF(COUNT(C8:G8)=5,"Completa","Falta") -> Falta
A9: B4-9178 | B9: Compila. Pasa los 10 pasos del harness. | C9: 3 | H9: =IF(COUNT(C9:G9)=5,SUM(C9:G9),"") | N9: =IF(COUNT(C9:G9)=5,"Completa","Falta") -> Falta
A10: B4-2076 | B10: Compila. Pasa los 10 pasos del harness. | C10: 3 | H10: =IF(COUNT(C10:G10)=5,SUM(C10:G10),"") | N10: =IF(COUNT(C10:G10)=5,"Completa","Falta") -> Falta
A11: B4-2916 | B11: Compila. Pasa los 10 pasos del harness. | C11: 3 | H11: =IF(COUNT(C11:G11)=5,SUM(C11:G11),"") | N11: =IF(COUNT(C11:G11)=5,"Completa","Falta") -> Falta
A12: B4-1844 | B12: Compila. Pasa los 10 pasos del harness. | C12: 3 | H12: =IF(COUNT(C12:G12)=5,SUM(C12:G12),"") | N12: =IF(COUNT(C12:G12)=5,"Completa","Falta") -> Falta
A13: B4-9939 | B13: Compila. Falla 3 de 10 pasos del harness (pasos 2,3,6; numerados desde 0). | H13: =IF(COUNT(C13:G13)=5,SUM(C13:G13),"") | N13: =IF(COUNT(C13:G13)=5,"Completa","Falta") -> Falta
A14: B4-9793 | B14: Compila. Falla 2 de 10 pasos del harness (pasos 3,6; numerados desde 0). | H14: =IF(COUNT(C14:G14)=5,SUM(C14:G14),"") | N14: =IF(COUNT(C14:G14)=5,"Completa","Falta") -> Falta
A15: B4-5174 | B15: Compila. Falla 4 de 10 pasos del harness (pasos 3,4,7,9; numerados desde 0). | H15: =IF(COUNT(C15:G15)=5,SUM(C15:G15),"") | N15: =IF(COUNT(C15:G15)=5,"Completa","Falta") -> Falta
A16: B4-1107 | B16: Compila. Pasa los 10 pasos del harness. | C16: 3 | H16: =IF(COUNT(C16:G16)=5,SUM(C16:G16),"") | N16: =IF(COUNT(C16:G16)=5,"Completa","Falta") -> Falta
A17: B4-2313 | B17: Compila. Falla 2 de 10 pasos del harness (pasos 3,6; numerados desde 0). | H17: =IF(COUNT(C17:G17)=5,SUM(C17:G17),"") | N17: =IF(COUNT(C17:G17)=5,"Completa","Falta") -> Falta
A18: B4-4978 | B18: Compila. Pasa los 10 pasos del harness. | C18: 3 | H18: =IF(COUNT(C18:G18)=5,SUM(C18:G18),"") | N18: =IF(COUNT(C18:G18)=5,"Completa","Falta") -> Falta
A19: B4-6326 | B19: Compila. Pasa los 10 pasos del harness. | C19: 3 | H19: =IF(COUNT(C19:G19)=5,SUM(C19:G19),"") | N19: =IF(COUNT(C19:G19)=5,"Completa","Falta") -> Falta
A20: B4-2461 | B20: Compila. Pasa los 10 pasos del harness. | C20: 3 | H20: =IF(COUNT(C20:G20)=5,SUM(C20:G20),"") | N20: =IF(COUNT(C20:G20)=5,"Completa","Falta") -> Falta
A21: B4-9948 | B21: Compila. Pasa los 10 pasos del harness. | C21: 3 | H21: =IF(COUNT(C21:G21)=5,SUM(C21:G21),"") | N21: =IF(COUNT(C21:G21)=5,"Completa","Falta") -> Falta
A22: B4-7421 | B22: Compila. Pasa los 10 pasos del harness. | C22: 3 | H22: =IF(COUNT(C22:G22)=5,SUM(C22:G22),"") | N22: =IF(COUNT(C22:G22)=5,"Completa","Falta") -> Falta
A23: B4-1969 | B23: Compila. Pasa los 10 pasos del harness. | C23: 3 | H23: =IF(COUNT(C23:G23)=5,SUM(C23:G23),"") | N23: =IF(COUNT(C23:G23)=5,"Completa","Falta") -> Falta
A24: B4-9599 | B24: Compila. Pasa los 10 pasos del harness. | C24: 3 | H24: =IF(COUNT(C24:G24)=5,SUM(C24:G24),"") | N24: =IF(COUNT(C24:G24)=5,"Completa","Falta") -> Falta
A25: B4-3739 | B25: Compila. Falla 1 de 10 pasos del harness (pasos 3; numerados desde 0). | H25: =IF(COUNT(C25:G25)=5,SUM(C25:G25),"") | N25: =IF(COUNT(C25:G25)=5,"Completa","Falta") -> Falta
A26: B4-1794 | B26: Compila. Pasa los 10 pasos del harness. | C26: 3 | H26: =IF(COUNT(C26:G26)=5,SUM(C26:G26),"") | N26: =IF(COUNT(C26:G26)=5,"Completa","Falta") -> Falta
A27: B4-9025 | B27: Compila. Pasa los 10 pasos del harness. | C27: 3 | H27: =IF(COUNT(C27:G27)=5,SUM(C27:G27),"") | N27: =IF(COUNT(C27:G27)=5,"Completa","Falta") -> Falta
A28: B4-7211 | B28: Compila. Falla 2 de 10 pasos del harness (pasos 3,6; numerados desde 0). | H28: =IF(COUNT(C28:G28)=5,SUM(C28:G28),"") | N28: =IF(COUNT(C28:G28)=5,"Completa","Falta") -> Falta
A29: B4-5930 | B29: Compila. Pasa los 10 pasos del harness. | C29: 3 | H29: =IF(COUNT(C29:G29)=5,SUM(C29:G29),"") | N29: =IF(COUNT(C29:G29)=5,"Completa","Falta") -> Falta

Sheet B5
A1: B5 — Ventilador con retardo a la desconexión (Basico)
A2: Lee cada respuesta por su código en respuestas/Respuestas_B5.html. Rellena solo las celdas amarillas. Las azules vienen de CODESYS o se calculan solas. La fila EJEMPLO no se analiza.
A4: Código | B4: Resultado en CODESYS (automático) | C4: Corrección funcional (0–3) | D4: Cumplimiento IEC (0–3) | E4: Coherencia lógica (0–3) | F4: Claridad estructural (0–3) | G4: Mantenibilidad (0–3) | H4: Total (0–15) | I4: Justificación: corrección funcional / IEC | J4: Justificación: coherencia | K4: Justificación: claridad | L4: Justificación: mantenibilidad | M4: Observaciones | N4: Estado
A5: EJEMPLO | B5: Compila. Falla 2 de 7 pasos del harness (pasos 3,5; numerados desde 0). | C5: 1 | D5: 2 | E5: 2 | F5: 2 | G5: 1 | H5: =IF(COUNT(C5:G5)=5,SUM(C5:G5),"") -> 8 | I5: Arranca y para, pero rearranca solo tras la emergencia. | J5: Sin contradicciones; transiciones completas. | K5: Nombres claros, comentarios útiles. | L5: El tiempo está escrito como literal en dos sitios. | N5: =IF(COUNT(C5:G5)=5,"Completa","Falta") -> Completa
A6: B5-9290 | B6: Compila. Pasa los 9 pasos del harness. | C6: 3 | H6: =IF(COUNT(C6:G6)=5,SUM(C6:G6),"") | N6: =IF(COUNT(C6:G6)=5,"Completa","Falta") -> Falta
A7: B5-7090 | B7: Compila. Falla 1 de 9 pasos del harness (pasos 0; numerados desde 0). | H7: =IF(COUNT(C7:G7)=5,SUM(C7:G7),"") | N7: =IF(COUNT(C7:G7)=5,"Completa","Falta") -> Falta
A8: B5-4470 | B8: Compila sola, pero no se pudo simular: declara las entradas donde el harness no puede escribirlas ('quemadorOn' no es ninguna entrada de 'FB_VENTILADOR'). | H8: =IF(COUNT(C8:G8)=5,SUM(C8:G8),"") | N8: =IF(COUNT(C8:G8)=5,"Completa","Falta") -> Falta
A9: B5-6632 | B9: Compila. Falla 5 de 9 pasos del harness (pasos 2,3,5,7,8; numerados desde 0). | H9: =IF(COUNT(C9:G9)=5,SUM(C9:G9),"") | N9: =IF(COUNT(C9:G9)=5,"Completa","Falta") -> Falta
A10: B5-4246 | B10: Compila. Falla 1 de 9 pasos del harness (pasos 0; numerados desde 0). | H10: =IF(COUNT(C10:G10)=5,SUM(C10:G10),"") | N10: =IF(COUNT(C10:G10)=5,"Completa","Falta") -> Falta
A11: B5-2235 | B11: Compila. Falla 1 de 9 pasos del harness (pasos 0; numerados desde 0). | H11: =IF(COUNT(C11:G11)=5,SUM(C11:G11),"") | N11: =IF(COUNT(C11:G11)=5,"Completa","Falta") -> Falta
A12: B5-6715 | B12: Compila. Pasa los 9 pasos del harness. | C12: 3 | H12: =IF(COUNT(C12:G12)=5,SUM(C12:G12),"") | N12: =IF(COUNT(C12:G12)=5,"Completa","Falta") -> Falta
A13: B5-8536 | B13: Compila. Falla 3 de 9 pasos del harness (pasos 0,5,7; numerados desde 0). | H13: =IF(COUNT(C13:G13)=5,SUM(C13:G13),"") | N13: =IF(COUNT(C13:G13)=5,"Completa","Falta") -> Falta
A14: B5-8802 | B14: Compila sola, pero no se pudo simular: declara las entradas donde el harness no puede escribirlas ('quemadorOn' no es ninguna entrada de 'FB_VENTILADOR'). | H14: =IF(COUNT(C14:G14)=5,SUM(C14:G14),"") | N14: =IF(COUNT(C14:G14)=5,"Completa","Falta") -> Falta
A15: B5-2103 | B15: Compila. Pasa los 9 pasos del harness. | C15: 3 | H15: =IF(COUNT(C15:G15)=5,SUM(C15:G15),"") | N15: =IF(COUNT(C15:G15)=5,"Completa","Falta") -> Falta
A16: B5-3077 | B16: Compila. Pasa los 9 pasos del harness. | C16: 3 | H16: =IF(COUNT(C16:G16)=5,SUM(C16:G16),"") | N16: =IF(COUNT(C16:G16)=5,"Completa","Falta") -> Falta
A17: B5-6054 | B17: Compila. Pasa los 9 pasos del harness. | C17: 3 | H17: =IF(COUNT(C17:G17)=5,SUM(C17:G17),"") | N17: =IF(COUNT(C17:G17)=5,"Completa","Falta") -> Falta
A18: B5-6571 | B18: Compila. Falla 1 de 9 pasos del harness (pasos 0; numerados desde 0). | H18: =IF(COUNT(C18:G18)=5,SUM(C18:G18),"") | N18: =IF(COUNT(C18:G18)=5,"Completa","Falta") -> Falta
A19: B5-9947 | B19: Compila. Falla 5 de 9 pasos del harness (pasos 2,3,5,7,8; numerados desde 0). | H19: =IF(COUNT(C19:G19)=5,SUM(C19:G19),"") | N19: =IF(COUNT(C19:G19)=5,"Completa","Falta") -> Falta
A20: B5-4296 | B20: Compila. Falla 1 de 9 pasos del harness (pasos 0; numerados desde 0). | H20: =IF(COUNT(C20:G20)=5,SUM(C20:G20),"") | N20: =IF(COUNT(C20:G20)=5,"Completa","Falta") -> Falta
A21: B5-7882 | B21: Compila. Falla 2 de 9 pasos del harness (pasos 0,7; numerados desde 0). | H21: =IF(COUNT(C21:G21)=5,SUM(C21:G21),"") | N21: =IF(COUNT(C21:G21)=5,"Completa","Falta") -> Falta
A22: B5-6010 | B22: Compila. Falla 3 de 9 pasos del harness (pasos 0,5,7; numerados desde 0). | H22: =IF(COUNT(C22:G22)=5,SUM(C22:G22),"") | N22: =IF(COUNT(C22:G22)=5,"Completa","Falta") -> Falta
A23: B5-8869 | B23: Compila. Falla 2 de 9 pasos del harness (pasos 0,7; numerados desde 0). | H23: =IF(COUNT(C23:G23)=5,SUM(C23:G23),"") | N23: =IF(COUNT(C23:G23)=5,"Completa","Falta") -> Falta
A24: B5-8798 | B24: Compila sola, pero no se pudo simular: declara las entradas donde el harness no puede escribirlas ('quemadorOn' no es ninguna entrada de 'FB_VENTILADOR'). | H24: =IF(COUNT(C24:G24)=5,SUM(C24:G24),"") | N24: =IF(COUNT(C24:G24)=5,"Completa","Falta") -> Falta
A25: B5-2379 | B25: Compila. Pasa los 9 pasos del harness. | C25: 3 | H25: =IF(COUNT(C25:G25)=5,SUM(C25:G25),"") | N25: =IF(COUNT(C25:G25)=5,"Completa","Falta") -> Falta
A26: B5-8170 | B26: Compila. Pasa los 9 pasos del harness. | C26: 3 | H26: =IF(COUNT(C26:G26)=5,SUM(C26:G26),"") | N26: =IF(COUNT(C26:G26)=5,"Completa","Falta") -> Falta
A27: B5-2653 | B27: Compila. Falla 5 de 9 pasos del harness (pasos 2,3,5,7,8; numerados desde 0). | H27: =IF(COUNT(C27:G27)=5,SUM(C27:G27),"") | N27: =IF(COUNT(C27:G27)=5,"Completa","Falta") -> Falta
A28: B5-2367 | B28: Compila. Falla 2 de 9 pasos del harness (pasos 0,7; numerados desde 0). | H28: =IF(COUNT(C28:G28)=5,SUM(C28:G28),"") | N28: =IF(COUNT(C28:G28)=5,"Completa","Falta") -> Falta
A29: B5-3623 | B29: Compila. Falla 3 de 9 pasos del harness (pasos 2,5,7; numerados desde 0). | H29: =IF(COUNT(C29:G29)=5,SUM(C29:G29),"") | N29: =IF(COUNT(C29:G29)=5,"Completa","Falta") -> Falta

Sheet B6
A1: B6 — Baliza intermitente (Basico)
A2: Lee cada respuesta por su código en respuestas/Respuestas_B6.html. Rellena solo las celdas amarillas. Las azules vienen de CODESYS o se calculan solas. La fila EJEMPLO no se analiza.
A4: Código | B4: Resultado en CODESYS (automático) | C4: Corrección funcional (0–3) | D4: Cumplimiento IEC (0–3) | E4: Coherencia lógica (0–3) | F4: Claridad estructural (0–3) | G4: Mantenibilidad (0–3) | H4: Total (0–15) | I4: Justificación: corrección funcional / IEC | J4: Justificación: coherencia | K4: Justificación: claridad | L4: Justificación: mantenibilidad | M4: Observaciones | N4: Estado
A5: EJEMPLO | B5: Compila. Falla 2 de 7 pasos del harness (pasos 3,5; numerados desde 0). | C5: 1 | D5: 2 | E5: 2 | F5: 2 | G5: 1 | H5: =IF(COUNT(C5:G5)=5,SUM(C5:G5),"") -> 8 | I5: Arranca y para, pero rearranca solo tras la emergencia. | J5: Sin contradicciones; transiciones completas. | K5: Nombres claros, comentarios útiles. | L5: El tiempo está escrito como literal en dos sitios. | N5: =IF(COUNT(C5:G5)=5,"Completa","Falta") -> Completa
A6: B6-4934 | B6: Compila. Falla 1 de 3 pasos del harness (pasos 1; numerados desde 0). | H6: =IF(COUNT(C6:G6)=5,SUM(C6:G6),"") | N6: =IF(COUNT(C6:G6)=5,"Completa","Falta") -> Falta
A7: B6-2374 | B7: Compila. Falla 1 de 3 pasos del harness (pasos 1; numerados desde 0). | H7: =IF(COUNT(C7:G7)=5,SUM(C7:G7),"") | N7: =IF(COUNT(C7:G7)=5,"Completa","Falta") -> Falta
A8: B6-5301 | B8: Compila. Pasa los 3 pasos del harness. | C8: 3 | H8: =IF(COUNT(C8:G8)=5,SUM(C8:G8),"") | N8: =IF(COUNT(C8:G8)=5,"Completa","Falta") -> Falta
A9: B6-5850 | B9: Compila. Pasa los 3 pasos del harness. | C9: 3 | H9: =IF(COUNT(C9:G9)=5,SUM(C9:G9),"") | N9: =IF(COUNT(C9:G9)=5,"Completa","Falta") -> Falta
A10: B6-8282 | B10: Compila. Pasa los 3 pasos del harness. | C10: 3 | H10: =IF(COUNT(C10:G10)=5,SUM(C10:G10),"") | N10: =IF(COUNT(C10:G10)=5,"Completa","Falta") -> Falta
A11: B6-1513 | B11: Compila. Falla 1 de 3 pasos del harness (pasos 1; numerados desde 0). | H11: =IF(COUNT(C11:G11)=5,SUM(C11:G11),"") | N11: =IF(COUNT(C11:G11)=5,"Completa","Falta") -> Falta
A12: B6-5704 | B12: Compila. Falla 1 de 3 pasos del harness (pasos 1; numerados desde 0). | H12: =IF(COUNT(C12:G12)=5,SUM(C12:G12),"") | N12: =IF(COUNT(C12:G12)=5,"Completa","Falta") -> Falta
A13: B6-2528 | B13: Compila. Pasa los 3 pasos del harness. | C13: 3 | H13: =IF(COUNT(C13:G13)=5,SUM(C13:G13),"") | N13: =IF(COUNT(C13:G13)=5,"Completa","Falta") -> Falta
A14: B6-6083 | B14: Compila. Pasa los 3 pasos del harness. | C14: 3 | H14: =IF(COUNT(C14:G14)=5,SUM(C14:G14),"") | N14: =IF(COUNT(C14:G14)=5,"Completa","Falta") -> Falta
A15: B6-8430 | B15: Compila. Pasa los 3 pasos del harness. | C15: 3 | H15: =IF(COUNT(C15:G15)=5,SUM(C15:G15),"") | N15: =IF(COUNT(C15:G15)=5,"Completa","Falta") -> Falta
A16: B6-6488 | B16: Compila. Pasa los 3 pasos del harness. | C16: 3 | H16: =IF(COUNT(C16:G16)=5,SUM(C16:G16),"") | N16: =IF(COUNT(C16:G16)=5,"Completa","Falta") -> Falta
A17: B6-9731 | B17: Compila. Falla 1 de 3 pasos del harness (pasos 1; numerados desde 0). | H17: =IF(COUNT(C17:G17)=5,SUM(C17:G17),"") | N17: =IF(COUNT(C17:G17)=5,"Completa","Falta") -> Falta
A18: B6-2737 | B18: Compila. Pasa los 3 pasos del harness. | C18: 3 | H18: =IF(COUNT(C18:G18)=5,SUM(C18:G18),"") | N18: =IF(COUNT(C18:G18)=5,"Completa","Falta") -> Falta
A19: B6-7900 | B19: Compila. Falla 1 de 3 pasos del harness (pasos 1; numerados desde 0). | H19: =IF(COUNT(C19:G19)=5,SUM(C19:G19),"") | N19: =IF(COUNT(C19:G19)=5,"Completa","Falta") -> Falta
A20: B6-3083 | B20: Compila. Pasa los 3 pasos del harness. | C20: 3 | H20: =IF(COUNT(C20:G20)=5,SUM(C20:G20),"") | N20: =IF(COUNT(C20:G20)=5,"Completa","Falta") -> Falta
A21: B6-2545 | B21: Compila. Pasa los 3 pasos del harness. | C21: 3 | H21: =IF(COUNT(C21:G21)=5,SUM(C21:G21),"") | N21: =IF(COUNT(C21:G21)=5,"Completa","Falta") -> Falta
A22: B6-7904 | B22: Compila. Pasa los 3 pasos del harness. | C22: 3 | H22: =IF(COUNT(C22:G22)=5,SUM(C22:G22),"") | N22: =IF(COUNT(C22:G22)=5,"Completa","Falta") -> Falta
A23: B6-5267 | B23: Compila. Pasa los 3 pasos del harness. | C23: 3 | H23: =IF(COUNT(C23:G23)=5,SUM(C23:G23),"") | N23: =IF(COUNT(C23:G23)=5,"Completa","Falta") -> Falta
A24: B6-2365 | B24: Compila. Pasa los 3 pasos del harness. | C24: 3 | H24: =IF(COUNT(C24:G24)=5,SUM(C24:G24),"") | N24: =IF(COUNT(C24:G24)=5,"Completa","Falta") -> Falta
A25: B6-3667 | B25: Compila. Pasa los 3 pasos del harness. | C25: 3 | H25: =IF(COUNT(C25:G25)=5,SUM(C25:G25),"") | N25: =IF(COUNT(C25:G25)=5,"Completa","Falta") -> Falta
A26: B6-7194 | B26: Compila. Pasa los 3 pasos del harness. | C26: 3 | H26: =IF(COUNT(C26:G26)=5,SUM(C26:G26),"") | N26: =IF(COUNT(C26:G26)=5,"Completa","Falta") -> Falta
A27: B6-1976 | B27: Compila. Pasa los 3 pasos del harness. | C27: 3 | H27: =IF(COUNT(C27:G27)=5,SUM(C27:G27),"") | N27: =IF(COUNT(C27:G27)=5,"Completa","Falta") -> Falta
A28: B6-9476 | B28: Compila. Falla 1 de 3 pasos del harness (pasos 1; numerados desde 0). | H28: =IF(COUNT(C28:G28)=5,SUM(C28:G28),"") | N28: =IF(COUNT(C28:G28)=5,"Completa","Falta") -> Falta
A29: B6-1094 | B29: Compila. Pasa los 3 pasos del harness. | C29: 3 | H29: =IF(COUNT(C29:G29)=5,SUM(C29:G29),"") | N29: =IF(COUNT(C29:G29)=5,"Completa","Falta") -> Falta

Sheet B7
A1: B7 — Selector manual/automático (POU a elección) (Basico)
A2: Lee cada respuesta por su código en respuestas/Respuestas_B7.html. Rellena solo las celdas amarillas. Las azules vienen de CODESYS o se calculan solas. La fila EJEMPLO no se analiza.
A4: Código | B4: Resultado en CODESYS (automático) | C4: Corrección funcional (0–3) | D4: Cumplimiento IEC (0–3) | E4: Coherencia lógica (0–3) | F4: Claridad estructural (0–3) | G4: Mantenibilidad (0–3) | H4: Total (0–15) | I4: Justificación: corrección funcional / IEC | J4: Justificación: coherencia | K4: Justificación: claridad | L4: Justificación: mantenibilidad | M4: Observaciones | N4: Estado
A5: EJEMPLO | B5: Compila. Falla 2 de 7 pasos del harness (pasos 3,5; numerados desde 0). | C5: 1 | D5: 2 | E5: 2 | F5: 2 | G5: 1 | H5: =IF(COUNT(C5:G5)=5,SUM(C5:G5),"") -> 8 | I5: Arranca y para, pero rearranca solo tras la emergencia. | J5: Sin contradicciones; transiciones completas. | K5: Nombres claros, comentarios útiles. | L5: El tiempo está escrito como literal en dos sitios. | N5: =IF(COUNT(C5:G5)=5,"Completa","Falta") -> Completa
A6: B7-9815 | B6: Compila. Pasa los 10 pasos del harness. | C6: 3 | H6: =IF(COUNT(C6:G6)=5,SUM(C6:G6),"") | N6: =IF(COUNT(C6:G6)=5,"Completa","Falta") -> Falta
A7: B7-2790 | B7: Compila. Pasa los 10 pasos del harness. | C7: 3 | H7: =IF(COUNT(C7:G7)=5,SUM(C7:G7),"") | N7: =IF(COUNT(C7:G7)=5,"Completa","Falta") -> Falta
A8: B7-2011 | B8: Compila. Pasa los 10 pasos del harness. | C8: 3 | H8: =IF(COUNT(C8:G8)=5,SUM(C8:G8),"") | N8: =IF(COUNT(C8:G8)=5,"Completa","Falta") -> Falta
A9: B7-9657 | B9: Compila. Pasa los 10 pasos del harness. | C9: 3 | H9: =IF(COUNT(C9:G9)=5,SUM(C9:G9),"") | N9: =IF(COUNT(C9:G9)=5,"Completa","Falta") -> Falta
A10: B7-9128 | B10: Compila. Pasa los 10 pasos del harness. | C10: 3 | H10: =IF(COUNT(C10:G10)=5,SUM(C10:G10),"") | N10: =IF(COUNT(C10:G10)=5,"Completa","Falta") -> Falta
A11: B7-4683 | B11: Compila. Pasa los 10 pasos del harness. | C11: 3 | H11: =IF(COUNT(C11:G11)=5,SUM(C11:G11),"") | N11: =IF(COUNT(C11:G11)=5,"Completa","Falta") -> Falta
A12: B7-2454 | B12: Compila. Pasa los 10 pasos del harness. | C12: 3 | H12: =IF(COUNT(C12:G12)=5,SUM(C12:G12),"") | N12: =IF(COUNT(C12:G12)=5,"Completa","Falta") -> Falta
A13: B7-5501 | B13: Compila. Pasa los 10 pasos del harness. | C13: 3 | H13: =IF(COUNT(C13:G13)=5,SUM(C13:G13),"") | N13: =IF(COUNT(C13:G13)=5,"Completa","Falta") -> Falta
A14: B7-1125 | B14: Compila. Pasa los 10 pasos del harness. | C14: 3 | H14: =IF(COUNT(C14:G14)=5,SUM(C14:G14),"") | N14: =IF(COUNT(C14:G14)=5,"Completa","Falta") -> Falta
A15: B7-3058 | B15: Compila. Pasa los 10 pasos del harness. | C15: 3 | H15: =IF(COUNT(C15:G15)=5,SUM(C15:G15),"") | N15: =IF(COUNT(C15:G15)=5,"Completa","Falta") -> Falta
A16: B7-1392 | B16: Compila. Pasa los 10 pasos del harness. | C16: 3 | H16: =IF(COUNT(C16:G16)=5,SUM(C16:G16),"") | N16: =IF(COUNT(C16:G16)=5,"Completa","Falta") -> Falta
A17: B7-8494 | B17: Compila. Pasa los 10 pasos del harness. | C17: 3 | H17: =IF(COUNT(C17:G17)=5,SUM(C17:G17),"") | N17: =IF(COUNT(C17:G17)=5,"Completa","Falta") -> Falta
... A20: B7-1829 | B20: Compila. Pasa los 10 pasos del harness. | C20: 3 | H20: =IF(COUNT(C20:G20)=5,SUM(C20:G20),"") | N20: =IF(COUNT(C20:G20)=5,"Completa","Falta") -> Falta
A21: B7-4839 | B21: Compila sola, pero no se pudo simular: declara las entradas donde el harness no puede escribirlas ('modoAuto' no es ninguna entrada de 'SELBOMBA'). | H21: =IF(COUNT(C21:G21)=5,SUM(C21:G21),"") | N21: =IF(COUNT(C21:G21)=5,"Completa","Falta") -> Falta
A22: B7-7130 | B22: Compila. Pasa los 10 pasos del harness. | C22: 3 | H22: =IF(COUNT(C22:G22)=5,SUM(C22:G22),"") | N22: =IF(COUNT(C22:G22)=5,"Completa","Falta") -> Falta
A23: B7-3281 | B23: Compila. Pasa los 10 pasos del harness. | C23: 3 | H23: =IF(COUNT(C23:G23)=5,SUM(C23:G23),"") | N23: =IF(COUNT(C23:G23)=5,"Completa","Falta") -> Falta
A24: B7-2340 | B24: Compila sola, pero no se pudo simular: declara las entradas donde el harness no puede escribirlas ('modoAuto' no es ninguna entrada de 'SELBOMBA'). | H24: =IF(COUNT(C24:G24)=5,SUM(C24:G24),"") | N24: =IF(COUNT(C24:G24)=5,"Completa","Falta") -> Falta
A25: B7-9455 | B25: Compila. Pasa los 10 pasos del harness. | C25: 3 | H25: =IF(COUNT(C25:G25)=5,SUM(C25:G25),"") | N25: =IF(COUNT(C25:G25)=5,"Completa","Falta") -> Falta
A26: B7-4620 | B26: Compila sola, pero no se pudo simular: declara las entradas donde el harness no puede escribirlas ('modoAuto' no es ninguna entrada de 'SELBOMBA'). | H26: =IF(COUNT(C26:G26)=5,SUM(C26:G26),"") | N26: =IF(COUNT(C26:G26)=5,"Completa","Falta") -> Falta
A27: B7-4833 | B27: Compila. Pasa los 10 pasos del harness. | C27: 3 | H27: =IF(COUNT(C27:G27)=5,SUM(C27:G27),"") | N27: =IF(COUNT(C27:G27)=5,"Completa","Falta") -> Falta
A28: B7-3239 | B28: Compila. Pasa los 10 pasos del harness. | C28: 3 | H28: =IF(COUNT(C28:G28)=5,SUM(C28:G28),"") | N28: =IF(COUNT(C28:G28)=5,"Completa","Falta") -> Falta
A29: B7-6425 | B29: Compila sola, pero no se pudo simular: declara las entradas donde el harness no puede escribirlas ('modoAuto' no es ninguna entrada de 'SELBOMBA'). | H29: =IF(COUNT(C29:G29)=5,SUM(C29:G29),"") | N29: =IF(COUNT(C29:G29)=5,"Completa","Falta") -> Falta

Sheet B8
A1: B8 — Conteo de eventos por flanco (Basico)
A2: Lee cada respuesta por su código en respuestas/Respuestas_B8.html. Rellena solo las celdas amarillas. Las azules vienen de CODESYS o se calculan solas. La fila EJEMPLO no se analiza.
A4: Código | B4: Resultado en CODESYS (automático) | C4: Corrección funcional (0–3) | D4: Cumplimiento IEC (0–3) | E4: Coherencia lógica (0–3) | F4: Claridad estructural (0–3) | G4: Mantenibilidad (0–3) | H4: Total (0–15) | I4: Justificación: corrección funcional / IEC | J4: Justificación: coherencia | K4: Justificación: claridad | L4: Justificación: mantenibilidad | M4: Observaciones | N4: Estado
A5: EJEMPLO | B5: Compila. Falla 2 de 7 pasos del harness (pasos 3,5; numerados desde 0). | C5: 1 | D5: 2 | E5: 2 | F5: 2 | G5: 1 | H5: =IF(COUNT(C5:G5)=5,SUM(C5:G5),"") -> 8 | I5: Arranca y para, pero rearranca solo tras la emergencia. | J5: Sin contradicciones; transiciones completas. | K5: Nombres claros, comentarios útiles. | L5: El tiempo está escrito como literal en dos sitios. | N5: =IF(COUNT(C5:G5)=5,"Completa","Falta") -> Completa
A6: B8-2855 | B6: Compila. Pasa los 9 pasos del harness. | C6: 3 | H6: =IF(COUNT(C6:G6)=5,SUM(C6:G6),"") | N6: =IF(COUNT(C6:G6)=5,"Completa","Falta") -> Falta
A7: B8-2057 | B7: Compila. Falla 7 de 9 pasos del harness (pasos 1,2,3,4,5,6,8; numerados desde 0). | H7: =IF(COUNT(C7:G7)=5,SUM(C7:G7),"") | N7: =IF(COUNT(C7:G7)=5,"Completa","Falta") -> Falta
A8: B8-3959 | B8: Compila. Pasa los 9 pasos del harness. | C8: 3 | H8: =IF(COUNT(C8:G8)=5,SUM(C8:G8),"") | N8: =IF(COUNT(C8:G8)=5,"Completa","Falta") -> Falta
A9: B8-6962 | B9: Compila. Pasa los 9 pasos del harness. | C9: 3 | H9: =IF(COUNT(C9:G9)=5,SUM(C9:G9),"") | N9: =IF(COUNT(C9:G9)=5,"Completa","Falta") -> Falta
A10: B8-4908 | B10: Compila. Pasa los 9 pasos del harness. | C10: 3 | H10: =IF(COUNT(C10:G10)=5,SUM(C10:G10),"") | N10: =IF(COUNT(C10:G10)=5,"Completa","Falta") -> Falta
A11: B8-3439 | B11: Compila. Pasa los 9 pasos del harness. | C11: 3 | H11: =IF(COUNT(C11:G11)=5,SUM(C11:G11),"") | N11: =IF(COUNT(C11:G11)=5,"Completa","Falta") -> Falta
A12: B8-1092 | B12: Compila. Pasa los 9 pasos del harness. | C12: 3 | H12: =IF(COUNT(C12:G12)=5,SUM(C12:G12),"") | N12: =IF(COUNT(C12:G12)=5,"Completa","Falta") -> Falta
A13: B8-3080 | B13: Compila. Pasa los 9 pasos del harness. | C13: 3 | H13: =IF(COUNT(C13:G13)=5,SUM(C13:G13),"") | N13: =IF(COUNT(C13:G13)=5,"Completa","Falta") -> Falta
A14: B8-6589 | B14: Compila. Pasa los 9 pasos del harness. | C14: 3 | H14: =IF(COUNT(C14:G14)=5,SUM(C14:G14),"") | N14: =IF(COUNT(C14:G14)=5,"Completa","Falta") -> Falta
A15: B8-2238 | B15: Compila. Pasa los 9 pasos del harness. | C15: 3 | H15: =IF(COUNT(C15:G15)=5,SUM(C15:G15),"") | N15: =IF(COUNT(C15:G15)=5,"Completa","Falta") -> Falta
A16: B8-4457 | B16: Compila. Pasa los 9 pasos del harness. | C16: 3 | H16: =IF(COUNT(C16:G16)=5,SUM(C16:G16),"") | N16: =IF(COUNT(C16:G16)=5,"Completa","Falta") -> Falta
A17: B8-7031 | B17: Compila. Pasa los 9 pasos del harness. | C17: 3 | H17: =IF(COUNT(C17:G17)=5,SUM(C17:G17),"") | N17: =IF(COUNT(C17:G17)=5,"Completa","Falta") -> Falta
A18: B8-9508 | B18: Compila. Pasa los 9 pasos del harness. | C18: 3 | H18: =IF(COUNT(C18:G18)=5,SUM(C18:G18),"") | N18: =IF(COUNT(C18:G18)=5,"Completa","Falta") -> Falta
A19: B8-3862 | B19: Compila. Pasa los 9 pasos del harness. | C19: 3 | H19: =IF(COUNT(C19:G19)=5,SUM(C19:G19),"") | N19: =IF(COUNT(C19:G19)=5,"Completa","Falta") -> Falta
... A29: B8-2626 | B29: Compila. Pasa los 9 pasos del harness. | C29: 3 | H29: =IF(COUNT(C29:G29)=5,SUM(C29:G29),"") | N29: =IF(COUNT(C29:G29)=5,"Completa","Falta") -> Falta

Sheet I1
A1: I1 — Semáforo con secuencia temporizada (Intermedio)
A2: Lee cada respuesta por su código en respuestas/Respuestas_I1.html. Rellena solo las celdas amarillas. Las azules vienen de CODESYS o se calculan solas. La fila EJEMPLO no se analiza.
A4: Código | B4: Resultado en CODESYS (automático) | C4: Corrección funcional (0–3) | D4: Cumplimiento IEC (0–3) | E4: Coherencia lógica (0–3) | F4: Claridad estructural (0–3) | G4: Mantenibilidad (0–3) | H4: Total (0–15) | I4: Justificación: corrección funcional / IEC | J4: Justificación: coherencia | K4: Justificación: claridad | L4: Justificación: mantenibilidad | M4: Observaciones | N4: Estado
A5: EJEMPLO | B5: Compila. Falla 2 de 7 pasos del harness (pasos 3,5; numerados desde 0). | C5: 1 | D5: 2 | E5: 2 | F5: 2 | G5: 1 | H5: =IF(COUNT(C5:G5)=5,SUM(C5:G5),"") -> 8 | I5: Arranca y para, pero rearranca solo tras la emergencia. | J5: Sin contradicciones; transiciones completas. | K5: Nombres claros, comentarios útiles. | L5: El tiempo está escrito como literal en dos sitios. | N5: =IF(COUNT(C5:G5)=5,"Completa","Falta") -> Completa
A6: I1-2135 | B6: Compila. Pasa los 9 pasos del harness. | C6: 3 | H6: =IF(COUNT(C6:G6)=5,SUM(C6:G6),"") | N6: =IF(COUNT(C6:G6)=5,"Completa","Falta") -> Falta
A7: I1-7364 | B7: Compila. Falla 6 de 9 pasos del harness (pasos 0,2,3,6,7,8; numerados desde 0). | H7: =IF(COUNT(C7:G7)=5,SUM(C7:G7),"") | N7: =IF(COUNT(C7:G7)=5,"Completa","Falta") -> Falta
A8: I1-5111 | B8: Compila. Falla 1 de 9 pasos del harness (pasos 7; numerados desde 0). | H8: =IF(COUNT(C8:G8)=5,SUM(C8:G8),"") | N8: =IF(COUNT(C8:G8)=5,"Completa","Falta") -> Falta
A9: I1-7969 | B9: Compila. Falla 7 de 9 pasos del harness (pasos 2,3,4,5,6,7,8; numerados desde 0). | H9: =IF(COUNT(C9:G9)=5,SUM(C9:G9),"") | N9: =IF(COUNT(C9:G9)=5,"Completa","Falta") -> Falta
A10: I1-5434 | B10: Compila. Pasa los 9 pasos del harness. | C10: 3 | H10: =IF(COUNT(C10:G10)=5,SUM(C10:G10),"") | N10: =IF(COUNT(C10:G10)=5,"Completa","Falta") -> Falta
A11: I1-7084 | B11: Compila. Pasa los 9 pasos del harness. | C11: 3 | H11: =IF(COUNT(C11:G11)=5,SUM(C11:G11),"") | N11: =IF(COUNT(C11:G11)=5,"Completa","Falta") -> Falta
A12: I1-2168 | B12: Compila. Pasa los 9 pasos del harness. | C12: 3 | H12: =IF(COUNT(C12:G12)=5,SUM(C12:G12),"") | N12: =IF(COUNT(C12:G12)=5,"Completa","Falta") -> Falta
A13: I1-3359 | B13: Compila. Pasa los 9 pasos del harness. | C13: 3 | H13: =IF(COUNT(C13:G13)=5,SUM(C13:G13),"") | N13: =IF(COUNT(C13:G13)=5,"Completa","Falta") -> Falta
A14: I1-8741 | B14: Compila sola, pero no se pudo simular: declara las entradas donde el harness no puede escribirlas ('habilitado' no es ninguna entrada de 'FB_SEMAFORO'). | H14: =IF(COUNT(C14:G14)=5,SUM(C14:G14),"") | N14: =IF(COUNT(C14:G14)=5,"Completa","Falta") -> Falta
A15: I1-4990 | B15: Compila. Falla 1 de 9 pasos del harness (pasos 7; numerados desde 0). | H15: =IF(COUNT(C15:G15)=5,SUM(C15:G15),"") | N15: =IF(COUNT(C15:G15)=5,"Completa","Falta") -> Falta
A16: I1-8830 | B16: Compila. Pasa los 9 pasos del harness. | C16: 3 | H16: =IF(COUNT(C16:G16)=5,SUM(C16:G16),"") | N16: =IF(COUNT(C16:G16)=5,"Completa","Falta") -> Falta
A17: I1-7322 | B17: Compila. Pasa los 9 pasos del harness. | C17: 3 | H17: =IF(COUNT(C17:G17)=5,SUM(C17:G17),"") | N17: =IF(COUNT(C17:G17)=5,"Completa","Falta") -> Falta
A18: I1-3250 | B18: Compila. Pasa los 9 pasos del harness. | C18: 3 | H18: =IF(COUNT(C18:G18)=5,SUM(C18:G18),"") | N18: =IF(COUNT(C18:G18)=5,"Completa","Falta") -> Falta
A19: I1-3464 | B19: Compila. Pasa los 9 pasos del harness. | C19: 3 | H19: =IF(COUNT(C19:G19)=5,SUM(C19:G19),"") | N19: =IF(COUNT(C19:G19)=5,"Completa","Falta") -> Falta
A20: I1-8420 | B20: Compila. Falla 8 de 9 pasos del harness (pasos 1,2,3,4,5,6,7,8; numerados desde 0). | H20: =IF(COUNT(C20:G20)=5,SUM(C20:G20),"") | N20: =IF(COUNT(C20:G20)=5,"Completa","Falta") -> Falta
A21: I1-5295 | B21: Compila. Falla 7 de 9 pasos del harness (pasos 2,3,4,5,6,7,8; numerados desde 0). | H21: =IF(COUNT(C21:G21)=5,SUM(C21:G21),"") | N21: =IF(COUNT(C21:G21)=5,"Completa","Falta") -> Falta
A22: I1-8541 | B22: Compila. Pasa los 9 pasos del harness. | C22: 3 | H22: =IF(COUNT(C22:G22)=5,SUM(C22:G22),"") | N22: =IF(COUNT(C22:G22)=5,"Completa","Falta") -> Falta
A23: I1-4916 | B23: No compila (20 errores). | C23: 0 | D23: 0 | H23: =IF(COUNT(C23:G23)=5,SUM(C23:G23),"") | N23: =IF(COUNT(C23:G23)=5,"Completa","Falta") -> Falta
A24: I1-5056 | B24: Compila. Falla 1 de 9 pasos del harness (pasos 7; numerados desde 0). | H24: =IF(COUNT(C24:G24)=5,SUM(C24:G24),"") | N24: =IF(COUNT(C24:G24)=5,"Completa","Falta") -> Falta
A25: I1-1955 | B25: Compila. Falla 7 de 9 pasos del harness (pasos 2,3,4,5,6,7,8; numerados desde 0). | H25: =IF(COUNT(C25:G25)=5,SUM(C25:G25),"") | N25: =IF(COUNT(C25:G25)=5,"Completa","Falta") -> Falta
A26: I1-8761 | B26: Compila. Falla 6 de 9 pasos del harness (pasos 0,2,3,5,6,7; numerados desde 0). | H26: =IF(COUNT(C26:G26)=5,SUM(C26:G26),"") | N26: =IF(COUNT(C26:G26)=5,"Completa","Falta") -> Falta
A27: I1-4511 | B27: Compila. Pasa los 9 pasos del harness. | C27: 3 | H27: =IF(COUNT(C27:G27)=5,SUM(C27:G27),"") | N27: =IF(COUNT(C27:G27)=5,"Completa","Falta") -> Falta
A28: I1-4945 | B28: No compila (20 errores). | C28: 0 | D28: 0 | H28: =IF(COUNT(C28:G28)=5,SUM(C28:G28),"") | N28: =IF(COUNT(C28:G28)=5,"Completa","Falta") -> Falta
A29: I1-3124 | B29: Compila. Falla 1 de 9 pasos del harness (pasos 7; numerados desde 0). | H29: =IF(COUNT(C29:G29)=5,SUM(C29:G29),"") | N29: =IF(COUNT(C29:G29)=5,"Completa","Falta") -> Falta

Sheet I2
A1: I2 — FSM de llenado multietapa (Intermedio)
A2: Lee cada respuesta por su código en respuestas/Respuestas_I2.html. Rellena solo las celdas amarillas. Las azules vienen de CODESYS o se calculan solas. La fila EJEMPLO no se analiza.
A4: Código | B4: Resultado en CODESYS (automático) | C4: Corrección funcional (0–3) | D4: Cumplimiento IEC (0–3) | E4: Coherencia lógica (0–3) | F4: Claridad estructural (0–3) | G4: Mantenibilidad (0–3) | H4: Total (0–15) | I4: Justificación: corrección funcional / IEC | J4: Justificación: coherencia | K4: Justificación: claridad | L4: Justificación: mantenibilidad | M4: Observaciones | N4: Estado
A5: EJEMPLO | B5: Compila. Falla 2 de 7 pasos del harness (pasos 3,5; numerados desde 0). | C5: 1 | D5: 2 | E5: 2 | F5: 2 | G5: 1 | H5: =IF(COUNT(C5:G5)=5,SUM(C5:G5),"") -> 8 | I5: Arranca y para, pero rearranca solo tras la emergencia. | J5: Sin contradicciones; transiciones completas. | K5: Nombres claros, comentarios útiles. | L5: El tiempo está escrito como literal en dos sitios. | N5: =IF(COUNT(C5:G5)=5,"Completa","Falta") -> Completa
A6: I2-2212 | B6: Compila. Falla 4 de 12 pasos del harness (pasos 4,5,6,9; numerados desde 0). | H6: =IF(COUNT(C6:G6)=5,SUM(C6:G6),"") | N6: =IF(COUNT(C6:G6)=5,"Completa","Falta") -> Falta
A7: I2-8131 | B7: Compila. Pasa los 12 pasos del harness. | C7: 3 | H7: =IF(COUNT(C7:G7)=5,SUM(C7:G7),"") | N7: =IF(COUNT(C7:G7)=5,"Completa","Falta") -> Falta
A8: I2-4370 | B8: Compila. Falla 2 de 12 pasos del harness (pasos 2,3; numerados desde 0). | H8: =IF(COUNT(C8:G8)=5,SUM(C8:G8),"") | N8: =IF(COUNT(C8:G8)=5,"Completa","Falta") -> Falta
A9: I2-4324 | B9: Compila. Falla 7 de 12 pasos del harness (pasos 2,3,4,5,6,9,11; numerados desde 0). | H9: =IF(COUNT(C9:G9)=5,SUM(C9:G9),"") | N9: =IF(COUNT(C9:G9)=5,"Completa","Falta") -> Falta
A10: I2-4540 | B10: Compila. Falla 4 de 12 pasos del harness (pasos 2,3,4,9; numerados desde 0). | H10: =IF(COUNT(C10:G10)=5,SUM(C10:G10),"") | N10: =IF(COUNT(C10:G10)=5,"Completa","Falta") -> Falta
A11: I2-3499 | B11: Compila. Pasa los 12 pasos del harness. | C11: 3 | H11: =IF(COUNT(C11:G11)=5,SUM(C11:G11),"") | N11: =IF(COUNT(C11:G11)=5,"Completa","Falta") -> Falta
A12: I2-9002 | B12: Compila. Pasa los 12 pasos del harness. | C12: 3 | H12: =IF(COUNT(C12:G12)=5,SUM(C12:G12),"") | N12: =IF(COUNT(C12:G12)=5,"Completa","Falta") -> Falta
A13: I2-4041 | B13: Compila. Pasa los 12 pasos del harness. | C13: 3 | H13: =IF(COUNT(C13:G13)=5,SUM(C13:G13),"") | N13: =IF(COUNT(C13:G13)=5,"Completa","Falta") -> Falta
A14: I2-9360 | B14: Compila. Pasa los 12 pasos del harness. | C14: 3 | H14: =IF(COUNT(C14:G14)=5,SUM(C14:G14),"") | N14: =IF(COUNT(C14:G14)=5,"Completa","Falta") -> Falta
A15: I2-4337 | B15: Compila. Falla 2 de 12 pasos del harness (pasos 2,3; numerados desde 0). | H15: =IF(COUNT(C15:G15)=5,SUM(C15:G15),"") | N15: =IF(COUNT(C15:G15)=5,"Completa","Falta") -> Falta
A16: I2-3432 | B16: Compila sola, pero no se pudo simular: declara las entradas donde el harness no puede escribirlas ('nivelAlto' no es ninguna entrada de 'FB_LLENADO'). | H16: =IF(COUNT(C16:G16)=5,SUM(C16:G16),"") | N16: =IF(COUNT(C16:G16)=5,"Completa","Falta") -> Falta
A17: I2-3102 | B17: No compila (2 errores). | C17: 0 | D17: 0 | H17: =IF(COUNT(C17:G17)=5,SUM(C17:G17),"") | N17: =IF(COUNT(C17:G17)=5,"Completa","Falta") -> Falta
A18: I2-7023 | B18: Compila. Pasa los 12 pasos del harness. | C18: 3 | H18: =IF(COUNT(C18:G18)=5,SUM(C18:G18),"") | N18: =IF(COUNT(C18:G18)=5,"Completa","Falta") -> Falta
A19: I2-4582 | B19: Compila. Pasa los 12 pasos del harness. | C19: 3 | H19: =IF(COUNT(C19:G19)=5,SUM(C19:G19),"") | N19: =IF(COUNT(C19:G19)=5,"Completa","Falta") -> Falta
A20: I2-9998 | B20: Compila. Pasa los 12 pasos del harness. | C20: 3 | H20: =IF(COUNT(C20:G20)=5,SUM(C20:G20),"") | N20: =IF(COUNT(C20:G20)=5,"Completa","Falta") -> Falta
A21: I2-3377 | B21: Compila sola, pero no se pudo simular: declara las entradas donde el harness no puede escribirlas ('nivelAlto' no es ninguna entrada de 'FB_LLENADO'). | H21: =IF(COUNT(C21:G21)=5,SUM(C21:G21),"") | N21: =IF(COUNT(C21:G21)=5,"Completa","Falta") -> Falta
A22: I2-1039 | B22: Compila. Falla 5 de 12 pasos del harness (pasos 2,3,4,5,9; numerados desde 0). | H22: =IF(COUNT(C22:G22)=5,SUM(C22:G22),"") | N22: =IF(COUNT(C22:G22)=5,"Completa","Falta") -> Falta
A23: I2-2195 | B23: Compila. Falla 3 de 12 pasos del harness (pasos 4,5,6; numerados desde 0). | H23: =IF(COUNT(C23:G23)=5,SUM(C23:G23),"") | N23: =IF(COUNT(C23:G23)=5,"Completa","Falta") -> Falta
A24: I2-5294 | B24: Compila. Pasa los 12 pasos del harness. | C24: 3 | H24: =IF(COUNT(C24:G24)=5,SUM(C24:G24),"") | N24: =IF(COUNT(C24:G24)=5,"Completa","Falta") -> Falta
A25: I2-5330 | B25: Compila. Pasa los 12 pasos del harness. | C25: 3 | H25: =IF(COUNT(C25:G25)=5,SUM(C25:G25),"") | N25: =IF(COUNT(C25:G25)=5,"Completa","Falta") -> Falta
A26: I2-9686 | B26: Compila. Falla 3 de 12 pasos del harness (pasos 4,5,6; numerados desde 0). | H26: =IF(COUNT(C26:G26)=5,SUM(C26:G26),"") | N26: =IF(COUNT(C26:G26)=5,"Completa","Falta") -> Falta
A27: I2-7180 | B27: Compila. Falla 3 de 12 pasos del harness (pasos 4,5,6; numerados desde 0). | H27: =IF(COUNT(C27:G27)=5,SUM(C27:G27),"") | N27: =IF(COUNT(C27:G27)=5,"Completa","Falta") -> Falta
A28: I2-8425 | B28: Compila. Pasa los 12 pasos del harness. | C28: 3 | H28: =IF(COUNT(C28:G28)=5,SUM(C28:G28),"") | N28: =IF(COUNT(C28:G28)=5,"Completa","Falta") -> Falta
A29: I2-6794 | B29: Compila. Falla 3 de 12 pasos del harness (pasos 2,3,9; numerados desde 0). | H29: =IF(COUNT(C29:G29)=5,SUM(C29:G29),"") | N29: =IF(COUNT(C29:G29)=5,"Completa","Falta") -> Falta

Sheet I3
A1: I3 — Gestión de alarmas con prioridad (Intermedio)
A2: Lee cada respuesta por su código en respuestas/Respuestas_I3.html. Rellena solo las celdas amarillas. Las azules vienen de CODESYS o se calculan solas. La fila EJEMPLO no se analiza.
A4: Código | B4: Resultado en CODESYS (automático) | C4: Corrección funcional (0–3) | D4: Cumplimiento IEC (0–3) | E4: Coherencia lógica (0–3) | F4: Claridad estructural (0–3) | G4: Mantenibilidad (0–3) | H4: Total (0–15) | I4: Justificación: corrección funcional / IEC | J4: Justificación: coherencia | K4: Justificación: claridad | L4: Justificación: mantenibilidad | M4: Observaciones | N4: Estado
A5: EJEMPLO | B5: Compila. Falla 2 de 7 pasos del harness (pasos 3,5; numerados desde 0). | C5: 1 | D5: 2 | E5: 2 | F5: 2 | G5: 1 | H5: =IF(COUNT(C5:G5)=5,SUM(C5:G5),"") -> 8 | I5: Arranca y para, pero rearranca solo tras la emergencia. | J5: Sin contradicciones; transiciones completas. | K5: Nombres claros, comentarios útiles. | L5: El tiempo está escrito como literal en dos sitios. | N5: =IF(COUNT(C5:G5)=5,"Completa","Falta") -> Completa
A6: I3-8823 | B6: Compila. Pasa los 10 pasos del harness. | C6: 3 | H6: =IF(COUNT(C6:G6)=5,SUM(C6:G6),"") | N6: =IF(COUNT(C6:G6)=5,"Completa","Falta") -> Falta
A7: I3-1249 | B7: Compila. Pasa los 10 pasos del harness. | C7: 3 | H7: =IF(COUNT(C7:G7)=5,SUM(C7:G7),"") | N7: =IF(COUNT(C7:G7)=5,"Completa","Falta") -> Falta
A8: I3-2429 | B8: Compila. Pasa los 10 pasos del harness. | C8: 3 | H8: =IF(COUNT(C8:G8)=5,SUM(C8:G8),"") | N8: =IF(COUNT(C8:G8)=5,"Completa","Falta") -> Falta
